<?xml version="1.0"?>
<robot name="simplebox">
    <link name="world2"/>
    <link name="box">
    <visual>
      <geometry>
        <box size=".15 .15 .15"/>
      </geometry>
      <material name="silver">
        <color rgba="1 0 1 1"/>
      </material>
      <origin rpy="0 0 0" xyz="0 0 0"/>
    </visual>
<!--    <collision>-->
<!--      <geometry>-->
<!--        <box size=".15 .15 .15"/>-->
<!--      </geometry>-->
<!--      <origin rpy="0 0 0" xyz="0 0 0"/>-->
<!--    </collision>-->
        <inertial>
      <mass value="1.0"/>
      <origin rpy="0 0 0" xyz="0 0 0.15"/>
      <inertia ixx="0.02146" iyy="0.02146" izz="0.00125" ixy="0" ixz="0" iyz="0"/>
    </inertial>
    </link>
    <joint name="boxlink" type="continuous">
    <parent link="world2"/>
    <child link="box"/>
<!--        <axis xyz="0 0 1"/>-->
        <origin xyz="0 0 0.15" rpy="0 0 0"/>
    </joint>
</robot>